[2024-07-02T16:56:27.754+0000] {taskinstance.py:1979} INFO - Dependencies all met for dep_context=non-requeueable deps ti=<TaskInstance: dag_sentiment_analysis.extract_load manual__2024-07-02T16:56:26.559526+00:00 [queued]>
[2024-07-02T16:56:27.764+0000] {taskinstance.py:1979} INFO - Dependencies all met for dep_context=requeueable deps ti=<TaskInstance: dag_sentiment_analysis.extract_load manual__2024-07-02T16:56:26.559526+00:00 [queued]>
[2024-07-02T16:56:27.765+0000] {taskinstance.py:2193} INFO - Starting attempt 1 of 2
[2024-07-02T16:56:27.781+0000] {taskinstance.py:2217} INFO - Executing <Task(PythonOperator): extract_load> on 2024-07-02 16:56:26.559526+00:00
[2024-07-02T16:56:27.792+0000] {standard_task_runner.py:60} INFO - Started process 577 to run task
[2024-07-02T16:56:27.797+0000] {standard_task_runner.py:87} INFO - Running: ['***', 'tasks', 'run', 'dag_sentiment_analysis', 'extract_load', 'manual__2024-07-02T16:56:26.559526+00:00', '--job-id', '3', '--raw', '--subdir', 'DAGS_FOLDER/dag_sentiment_ana;ysis.py', '--cfg-path', '/tmp/tmp7g32n61f']
[2024-07-02T16:56:27.800+0000] {standard_task_runner.py:88} INFO - Job 3: Subtask extract_load
[2024-07-02T16:56:27.821+0000] {logging_mixin.py:188} WARNING - /home/***/.local/lib/python3.10/site-packages/***/settings.py:194 DeprecationWarning: The sql_alchemy_conn option in [core] has been moved to the sql_alchemy_conn option in [database] - the old setting has been used, but please update your config.
[2024-07-02T16:56:27.870+0000] {task_command.py:423} INFO - Running <TaskInstance: dag_sentiment_analysis.extract_load manual__2024-07-02T16:56:26.559526+00:00 [running]> on host 86a7095be55c
[2024-07-02T16:56:27.967+0000] {taskinstance.py:2513} INFO - Exporting env vars: AIRFLOW_CTX_DAG_OWNER='de-team' AIRFLOW_CTX_DAG_ID='dag_sentiment_analysis' AIRFLOW_CTX_TASK_ID='extract_load' AIRFLOW_CTX_EXECUTION_DATE='2024-07-02T16:56:26.559526+00:00' AIRFLOW_CTX_TRY_NUMBER='1' AIRFLOW_CTX_DAG_RUN_ID='manual__2024-07-02T16:56:26.559526+00:00'
[2024-07-02T16:56:30.098+0000] {taskinstance.py:2731} ERROR - Task failed with exception
Traceback (most recent call last):
  File "/home/airflow/.local/lib/python3.10/site-packages/airflow/models/taskinstance.py", line 444, in _execute_task
    result = _execute_callable(context=context, **execute_callable_kwargs)
  File "/home/airflow/.local/lib/python3.10/site-packages/airflow/models/taskinstance.py", line 414, in _execute_callable
    return execute_callable(context=context, **execute_callable_kwargs)
  File "/home/airflow/.local/lib/python3.10/site-packages/airflow/operators/python.py", line 200, in execute
    return_value = self.execute_callable()
  File "/home/airflow/.local/lib/python3.10/site-packages/airflow/operators/python.py", line 217, in execute_callable
    return self.python_callable(*self.op_args, **self.op_kwargs)
  File "/opt/airflow/plugins/finnhub_mongodb_loader.py", line 7, in extract_load
    collection = mongodb_loader.load('news', 'finnhub_news')
  File "/opt/airflow/plugins/mongodb_loader.py", line 24, in load
    mongo_client = get_mongo_client(mongo_uri)
  File "/opt/airflow/plugins/mongodb_loader.py", line 6, in get_mongo_client
    client = pymongo.MongoClient(mongo_uri)
  File "/home/airflow/.local/lib/python3.10/site-packages/pymongo/mongo_client.py", line 774, in __init__
    res = uri_parser.parse_uri(
  File "/home/airflow/.local/lib/python3.10/site-packages/pymongo/uri_parser.py", line 546, in parse_uri
    dns_resolver = _SrvResolver(fqdn, connect_timeout, srv_service_name, srv_max_hosts)
  File "/home/airflow/.local/lib/python3.10/site-packages/pymongo/srv_resolver.py", line 88, in __init__
    raise ConfigurationError(_INVALID_HOST_MSG % (fqdn,))
pymongo.errors.ConfigurationError: Invalid URI host: <your mongodb endpoint> is not a valid hostname for 'mongodb+srv://'. Did you mean to use 'mongodb://'?
[2024-07-02T16:56:30.116+0000] {taskinstance.py:1149} INFO - Marking task as UP_FOR_RETRY. dag_id=dag_sentiment_analysis, task_id=extract_load, execution_date=20240702T165626, start_date=20240702T165627, end_date=20240702T165630
[2024-07-02T16:56:30.131+0000] {standard_task_runner.py:107} ERROR - Failed to execute job 3 for task extract_load (Invalid URI host: <your mongodb endpoint> is not a valid hostname for 'mongodb+srv://'. Did you mean to use 'mongodb://'?; 577)
[2024-07-02T16:56:30.147+0000] {local_task_job_runner.py:234} INFO - Task exited with return code 1
[2024-07-02T16:56:30.169+0000] {taskinstance.py:3312} INFO - 0 downstream tasks scheduled from follow-on schedule check
